{"trial_id": "00", "hyperparameters": {"space": [{"class_name": "Int", "config": {"name": "filters", "default": null, "conditions": [], "min_value": 16, "max_value": 64, "step": 16, "sampling": "linear"}}, {"class_name": "Int", "config": {"name": "num_layers", "default": null, "conditions": [], "min_value": 1, "max_value": 3, "step": 1, "sampling": "linear"}}, {"class_name": "Int", "config": {"name": "filters_0", "default": null, "conditions": [], "min_value": 16, "max_value": 64, "step": 16, "sampling": "linear"}}, {"class_name": "Choice", "config": {"name": "kernel_size_0", "default": 3, "conditions": [], "values": [3, 5], "ordered": true}}, {"class_name": "Int", "config": {"name": "units", "default": null, "conditions": [], "min_value": 32, "max_value": 64, "step": 32, "sampling": "linear"}}, {"class_name": "Choice", "config": {"name": "learning_rate", "default": 0.01, "conditions": [], "values": [0.01, 0.001, 0.0001], "ordered": true}}], "values": {"filters": 64, "num_layers": 1, "filters_0": 16, "kernel_size_0": 5, "units": 64, "learning_rate": 0.01}}, "metrics": {"metrics": {}}, "score": null, "best_step": 0, "status": "FAILED", "message": "Traceback (most recent call last):\n  File \"/usr/local/lib/python3.8/dist-packages/keras_tuner/engine/base_tuner.py\", line 270, in _try_run_and_update_trial\n    self._run_and_update_trial(trial, *fit_args, **fit_kwargs)\n  File \"/usr/local/lib/python3.8/dist-packages/keras_tuner/engine/base_tuner.py\", line 235, in _run_and_update_trial\n    results = self.run_trial(trial, *fit_args, **fit_kwargs)\n  File \"/usr/local/lib/python3.8/dist-packages/keras_tuner/engine/tuner.py\", line 287, in run_trial\n    obj_value = self._build_and_fit_model(trial, *args, **copied_kwargs)\n  File \"/usr/local/lib/python3.8/dist-packages/keras_tuner/engine/tuner.py\", line 214, in _build_and_fit_model\n    results = self.hypermodel.fit(hp, model, *args, **kwargs)\n  File \"/usr/local/lib/python3.8/dist-packages/keras_tuner/engine/hypermodel.py\", line 144, in fit\n    return model.fit(*args, **kwargs)\n  File \"/usr/local/lib/python3.8/dist-packages/keras/utils/traceback_utils.py\", line 70, in error_handler\n    raise e.with_traceback(filtered_tb) from None\n  File \"/usr/local/lib/python3.8/dist-packages/tensorflow/python/framework/func_graph.py\", line 1200, in autograph_handler\n    raise e.ag_error_metadata.to_exception(e)\ntensorflow.python.framework.errors_impl.ResourceExhaustedError: in user code:\n\n    File \"/usr/local/lib/python3.8/dist-packages/keras/engine/training.py\", line 1284, in train_function  *\n        return step_function(self, iterator)\n    File \"/usr/local/lib/python3.8/dist-packages/keras/engine/training.py\", line 1268, in step_function  **\n        outputs = model.distribute_strategy.run(run_step, args=(data,))\n    File \"/usr/local/lib/python3.8/dist-packages/keras/engine/training.py\", line 1249, in run_step  **\n        outputs = model.train_step(data)\n    File \"/usr/local/lib/python3.8/dist-packages/keras/engine/training.py\", line 1050, in train_step\n        y_pred = self(x, training=True)\n    File \"/usr/local/lib/python3.8/dist-packages/keras/utils/traceback_utils.py\", line 70, in error_handler\n        raise e.with_traceback(filtered_tb) from None\n    File \"/usr/local/lib/python3.8/dist-packages/keras/backend.py\", line 2101, in random_uniform\n        return tf.random.stateless_uniform(\n\n    ResourceExhaustedError: Exception encountered when calling layer 'sequential' (type Sequential).\n    \n    {{function_node __wrapped__Mul_device_/job:localhost/replica:0/task:0/device:GPU:0}} failed to allocate memory [Op:Mul]\n    \n    Call arguments received by layer 'sequential' (type Sequential):\n      \u2022 inputs=tf.Tensor(shape=(None, 120, 120, 3), dtype=float32)\n      \u2022 training=True\n      \u2022 mask=None\n\n"}